<sdf version='1.6'>
  <model name='hummingbird'>
    <link name='base_link'>
      <pose frame=''>0 0 0 0 -0 0</pose>
      <inertial>
        <pose frame=''>-0.00612 2.2e-05 -0.052639 0 -0 0</pose>
        <mass>2.24682</mass>
        <inertia>
          <ixx>0.0242961</ixx>
          <ixy>-3.09634e-06</ixy>
          <ixz>-4.73268e-06</ixz>
          <iyy>0.0224294</iyy>
          <iyz>1.91916e-06</iyz>
          <izz>0.0236308</izz>
        </inertia>
      </inertial>
      <collision name='base_link_inertia_collision_1'>
        <pose frame=''>-0.03 0.2 -0.316 0 -0 0</pose>
        <geometry>
          <box>
            <size>0.3 0.2 0.01</size>
          </box>
        </geometry>
        <surface>
          <contact>
            <ode>
              <min_depth>0.001</min_depth>
              <max_vel>0</max_vel>
            </ode>
          </contact>
          <friction>
            <ode/>
          </friction>
        </surface>
      </collision>
      <collision name='base_link_inertia_collision_2'>
        <pose frame=''>-0.03 -0.2 -0.316 0 -0 0</pose>
        <geometry>
          <box>
            <size>0.3 0.2 0.01</size>
          </box>
        </geometry>
        <surface>
          <contact>
            <ode>
              <min_depth>0.001</min_depth>
              <max_vel>0</max_vel>
            </ode>
          </contact>
          <friction>
            <ode/>
          </friction>
        </surface>
      </collision>
      <visual name='base_link_inertia_visual_1'>
        <pose frame=''>0 0 0 0 -0 0</pose>
        <geometry>
          <mesh>
            <scale>1 1 1</scale>
            <uri>meshes/base_link.dae</uri>
          </mesh>
        </geometry>
        <material>
          <ambient>1 0 0 1</ambient>
          <diffuse>0.2 0.2 0.2 1.0</diffuse>
          <specular>0.4 0.4 0.4 1</specular>
          <emissive>0 0 0 0</emissive>
        </material>
      </visual>
      <visual name='base_link_fixed_joint_lump__battery_link_visual_2'>
        <pose frame=''>-0.024927 0 -0.059795 0 -0 0</pose>
        <geometry>
          <mesh>
            <scale>1 1 1</scale>
            <uri>meshes/battery_link.dae</uri>
          </mesh>
        </geometry>
      </visual>
      <visual name='base_link_fixed_joint_lump__camera_link_visual_3'>
        <pose frame=''>0.1549 0 -0.1325 1.5708 -0 1.5708</pose>
        <geometry>
          <mesh>
            <scale>1 1 1</scale>
            <uri>meshes/d435.dae</uri>
          </mesh>
        </geometry>
        <material>
          <script>
            <uri>__default__</uri>
            <name>__default__</name>
          </script>
        </material>
      </visual>
      <visual name='base_link_fixed_joint_lump__link_supporter_1_visual_4'>
        <pose frame=''>-0.00858 0.1135 -0.21299 0 -0 0</pose>
        <geometry>
          <mesh>
            <scale>1 1 1</scale>
            <uri>meshes/link_supporter_1.dae</uri>
          </mesh>
        </geometry>
      </visual>
      <visual name='base_link_fixed_joint_lump__link_supporter_2_visual_5'>
        <pose frame=''>-0.00858 -0.1135 -0.21299 0 -0 0</pose>
        <geometry>
          <mesh>
            <scale>1 1 1</scale>
            <uri>meshes/link_supporter_2.dae</uri>
          </mesh>
        </geometry>
      </visual>
      <velocity_decay/>
      <velocity_decay/>
      <self_collide>0</self_collide>
      <enable_wind>0</enable_wind>
      <kinematic>0</kinematic>
      <gravity>1</gravity>
      <sensor name='realsensecolor' type='camera'>
        <camera name='realsense'>
          <horizontal_fov>1.21126</horizontal_fov>
          <image>
            <width>640</width>
            <height>480</height>
            <format>RGB_INT8</format>
          </image>
          <clip>
            <near>0.1</near>
            <far>100</far>
          </clip>
          <noise>
            <type>gaussian</type>
            <mean>0</mean>
            <stddev>0.007</stddev>
          </noise>
        </camera>
        <always_on>1</always_on>
        <update_rate>60</update_rate>
        <visualize>1</visualize>
        <pose frame=''>0.14 0.0175 -0.1325 0 -0 0</pose>
      </sensor>
      <sensor name='realsenseired1' type='camera'>
        <camera name='realsense'>
          <horizontal_fov>1.21126</horizontal_fov>
          <image>
            <width>640</width>
            <height>480</height>
            <format>L_INT8</format>
          </image>
          <clip>
            <near>0.1</near>
            <far>100</far>
          </clip>
          <noise>
            <type>gaussian</type>
            <mean>0</mean>
            <stddev>0.005</stddev>
          </noise>
        </camera>
        <always_on>1</always_on>
        <update_rate>90</update_rate>
        <visualize>0</visualize>
        <pose frame=''>0.14 0.0175 -0.1325 0 -0 0</pose>
      </sensor>
      <sensor name='realsenseired2' type='camera'>
        <camera name='realsense'>
          <horizontal_fov>1.21126</horizontal_fov>
          <image>
            <width>640</width>
            <height>480</height>
            <format>L_INT8</format>
          </image>
          <clip>
            <near>0.1</near>
            <far>100</far>
          </clip>
          <noise>
            <type>gaussian</type>
            <mean>0</mean>
            <stddev>0.005</stddev>
          </noise>
        </camera>
        <always_on>1</always_on>
        <update_rate>90</update_rate>
        <visualize>0</visualize>
        <pose frame=''>0.14 0.0175 -0.1325 0 -0 0</pose>
      </sensor>
      <sensor name='realsensedepth' type='depth'>
        <camera name='realsense'>
          <horizontal_fov>1.21126</horizontal_fov>
          <image>
            <width>640</width>
            <height>480</height>
          </image>
          <clip>
            <near>0.1</near>
            <far>100</far>
          </clip>
          <noise>
            <type>gaussian</type>
            <mean>0</mean>
            <stddev>0.001</stddev>
          </noise>
        </camera>
        <always_on>1</always_on>
        <update_rate>90</update_rate>
        <visualize>0</visualize>
        <pose frame=''>0.14 0.0175 -0.1325 0 -0 0</pose>
      </sensor>
      <gravity>1</gravity>
      <velocity_decay/>
      <self_collide>0</self_collide>
      <gravity>1</gravity>
      <sensor name='imu_sensor' type='imu'>
        <always_on>1</always_on>
        <update_rate>200</update_rate>
        <visualize>1</visualize>
        <plugin name='imu_plugin' filename='libgazebo_ros_imu_sensor.so'>
          <topicName>d435i/imu</topicName>
          <bodyName>camera_link</bodyName>
          <updateRateHZ>200.0</updateRateHZ>
          <gaussianNoise>0.0</gaussianNoise>
          <xyzOffset>0.0 0.0 0.0</xyzOffset>
          <rpyOffset>0.0 0.0 0.0</rpyOffset>
          <frameName>imu_link_</frameName>
        </plugin>
        <pose frame=''>0.14 0.0175 -0.1325 0 -0 0</pose>
      </sensor>
    </link>
    <link name='imu_link'>
      <pose frame=''>0 0 0 0 -0 0</pose>
      <inertial>
        <pose frame=''>0 0 0 0 -0 0</pose>
        <mass>0.015</mass>
        <inertia>
          <ixx>1e-05</ixx>
          <ixy>0</ixy>
          <ixz>0</ixz>
          <iyy>1e-05</iyy>
          <iyz>0</iyz>
          <izz>1e-05</izz>
        </inertia>
      </inertial>
    </link>
    <joint name='imu_joint' type='revolute'>
      <child>imu_link</child>
      <parent>base_link</parent>
      <axis>
        <xyz>1 0 0</xyz>
        <limit>
          <lower>-2.96</lower>
          <upper>2.96</upper>
          <effort>300</effort>
          <velocity>10</velocity>
        </limit>
        <dynamics>
          <damping>0.5</damping>
          <friction>0</friction>
          <spring_reference>0</spring_reference>
          <spring_stiffness>0</spring_stiffness>
        </dynamics>
        <use_parent_model_frame>1</use_parent_model_frame>
      </axis>
    </joint>
    <link name='02DOF_frame1'>
      <pose frame=''>0.090596 0 -0.116 0 -0 0</pose>
      <inertial>
        <pose frame=''>0.033728 -0.000275 0.0246 0 -0 0</pose>
        <mass>0.19851</mass>
        <inertia>
          <ixx>0.000141122</ixx>
          <ixy>7.22807e-07</ixy>
          <ixz>4.64909e-08</ixz>
          <iyy>0.000771231</iyy>
          <iyz>-4.80458e-11</iyz>
          <izz>0.000878136</izz>
        </inertia>
      </inertial>
      <collision name='02DOF_frame1_collision'>
        <pose frame=''>0 0 0 0 -0 0</pose>
        <geometry>
          <mesh>
            <scale>1 1 1</scale>
            <uri>meshes/01DOF_frame0.STL</uri>
          </mesh>
        </geometry>
      </collision>
      <visual name='02DOF_frame1_visual'>
        <pose frame=''>0 0 0 0 -0 0</pose>
        <geometry>
          <mesh>
            <scale>1 1 1</scale>
            <uri>meshes/01DOF_frame0.STL</uri>
          </mesh>
        </geometry>
      </visual>
    </link>
    <joint name='joint1' type='revolute'>
      <child>02DOF_frame1</child>
      <parent>base_link</parent>
      <axis>
        <xyz>0 0 1</xyz>
        <limit>
          <lower>-3.14</lower>
          <upper>3.14</upper>
          <effort>300</effort>
          <velocity>5</velocity>
        </limit>
        <dynamics>
          <damping>0.5</damping>
          <friction>0</friction>
          <spring_reference>0</spring_reference>
          <spring_stiffness>0</spring_stiffness>
        </dynamics>
        <use_parent_model_frame>1</use_parent_model_frame>
      </axis>
    </joint>
    <link name='03DOF_frame2'>
      <pose frame=''>0.075096 1.1e-05 -0.116 1.5708 -0 -0.000716</pose>
      <inertial>
        <pose frame=''>0.086767 -0.000312 -0.000208 0 -0 0</pose>
        <mass>0.2776</mass>
        <inertia>
          <ixx>0.000104653</ixx>
          <ixy>-2.49293e-07</ixy>
          <ixz>1.61884e-07</ixz>
          <iyy>0.00124372</iyy>
          <iyz>1.99829e-08</iyz>
          <izz>0.00128333</izz>
        </inertia>
      </inertial>
      <collision name='03DOF_frame2_collision'>
        <pose frame=''>0 0 0 0 -0 0</pose>
        <geometry>
          <mesh>
            <scale>1 1 1</scale>
            <uri>meshes/02DOF_frame1.STL</uri>
          </mesh>
        </geometry>
      </collision>
      <visual name='03DOF_frame2_visual'>
        <pose frame=''>0 0 0 0 -0 0</pose>
        <geometry>
          <mesh>
            <scale>1 1 1</scale>
            <uri>meshes/02DOF_frame1.STL</uri>
          </mesh>
        </geometry>
      </visual>
    </link>
    <joint name='joint2' type='revolute'>
      <child>03DOF_frame2</child>
      <parent>02DOF_frame1</parent>
      <axis>
        <xyz>-0.000716 -1 -4e-06</xyz>
        <limit>
          <lower>-3.14</lower>
          <upper>0</upper>
          <effort>300</effort>
          <velocity>5</velocity>
        </limit>
        <dynamics>
          <damping>0.5</damping>
          <friction>0</friction>
          <spring_reference>0</spring_reference>
          <spring_stiffness>0</spring_stiffness>
        </dynamics>
        <use_parent_model_frame>1</use_parent_model_frame>
      </axis>
    </joint>
    <link name='04DOF_frame3'>
      <pose frame=''>0.304926 -0.000153 -0.116 -2.35619 -1.57079 -2.35691</pose>
      <inertial>
        <pose frame=''>-0.011032 -0.028798 -0.000519 0 -0 0</pose>
        <mass>0.1104</mass>
        <inertia>
          <ixx>2.01217e-05</ixx>
          <ixy>-2.20278e-06</ixy>
          <ixz>-1.99671e-08</ixz>
          <iyy>2.64982e-05</iyy>
          <iyz>4.80728e-11</iyz>
          <izz>3.25383e-05</izz>
        </inertia>
      </inertial>
      <collision name='04DOF_frame3_collision'>
        <pose frame=''>0 0 0 0 -0 0</pose>
        <geometry>
          <mesh>
            <scale>1 1 1</scale>
            <uri>meshes/04DOF_frame3.STL</uri>
          </mesh>
        </geometry>
      </collision>
      <visual name='04DOF_frame3_visual'>
        <pose frame=''>0 0 0 0 -0 0</pose>
        <geometry>
          <mesh>
            <scale>1 1 1</scale>
            <uri>meshes/04DOF_frame3.STL</uri>
          </mesh>
        </geometry>
      </visual>
    </link>
    <joint name='joint3' type='revolute'>
      <child>04DOF_frame3</child>
      <parent>03DOF_frame2</parent>
      <axis>
        <xyz>-0.000716 -0 -4e-06</xyz>
        <limit>
          <lower>-2.6</lower>
          <upper>2.6</upper>
          <effort>300</effort>
          <velocity>5</velocity>
        </limit>
        <dynamics>
          <damping>0.5</damping>
          <friction>0</friction>
          <spring_reference>0</spring_reference>
          <spring_stiffness>0</spring_stiffness>
        </dynamics>
        <use_parent_model_frame>1</use_parent_model_frame>
      </axis>
    </joint>
    <link name='05DOF_frame4'>
      <pose frame=''>0.415606 -0.000233 -0.116 -0.785394 -1.57079 -2.35691</pose>
      <inertial>
        <pose frame=''>0.007516 0.000239 -0.060749 0 -0 0</pose>
        <mass>0.091183</mass>
        <inertia>
          <ixx>3.26656e-05</ixx>
          <ixy>-1.99671e-08</ixy>
          <ixz>-2.20279e-06</ixz>
          <iyy>4.48618e-05</iyy>
          <iyz>2.00314e-08</iyz>
          <izz>3.56317e-05</izz>
        </inertia>
      </inertial>
      <collision name='05DOF_frame4_collision'>
        <pose frame=''>0 0 0 0 -0 0</pose>
        <geometry>
          <mesh>
            <scale>1 1 1</scale>
            <uri>meshes/05DOF_frame4.STL</uri>
          </mesh>
        </geometry>
      </collision>
      <visual name='05DOF_frame4_visual'>
        <pose frame=''>0 0 0 0 -0 0</pose>
        <geometry>
          <mesh>
            <scale>1 1 1</scale>
            <uri>meshes/05DOF_frame4.STL</uri>
          </mesh>
        </geometry>
      </visual>
    </link>
    <joint name='joint4' type='revolute'>
      <child>05DOF_frame4</child>
      <parent>04DOF_frame3</parent>
      <axis>
        <xyz>1 -0.000713 4e-06</xyz>
        <limit>
          <lower>-3.14</lower>
          <upper>3.14</upper>
          <effort>300</effort>
          <velocity>5</velocity>
        </limit>
        <dynamics>
          <damping>0.5</damping>
          <friction>0</friction>
          <spring_reference>0</spring_reference>
          <spring_stiffness>0</spring_stiffness>
        </dynamics>
        <use_parent_model_frame>1</use_parent_model_frame>
      </axis>
    </joint>
    <link name='06DOF_frame5'>
      <pose frame=''>0.415606 -0.000233 -0.116 -2.35619 -1.57079 -2.35691</pose>
      <inertial>
        <pose frame=''>-0.006829 -0.015759 -0.001178 0 -0 0</pose>
        <mass>0.10197</mass>
        <inertia>
          <ixx>2.44078e-05</ixx>
          <ixy>-1.53373e-06</ixy>
          <ixz>-2.86115e-08</ixz>
          <iyy>1.92192e-05</iyy>
          <iyz>-1.20279e-07</iyz>
          <izz>2.94503e-05</izz>
        </inertia>
      </inertial>
      <collision name='06DOF_frame5_collision'>
        <pose frame=''>0 0 0 0 -0 0</pose>
        <geometry>
          <mesh>
            <scale>1 1 1</scale>
            <uri>meshes/06DOF_frame5.STL</uri>
          </mesh>
        </geometry>
      </collision>
      <visual name='06DOF_frame5_visual'>
        <pose frame=''>0 0 0 0 -0 0</pose>
        <geometry>
          <mesh>
            <scale>1 1 1</scale>
            <uri>meshes/06DOF_frame5.STL</uri>
          </mesh>
        </geometry>
      </visual>
    </link>
    <joint name='joint5' type='revolute'>
      <child>06DOF_frame5</child>
      <parent>05DOF_frame4</parent>
      <axis>
        <xyz>-0.000716 -1 -4e-06</xyz>
        <limit>
          <lower>-1.5</lower>
          <upper>1.8</upper>
          <effort>300</effort>
          <velocity>5</velocity>
        </limit>
        <dynamics>
          <damping>0.5</damping>
          <friction>0</friction>
          <spring_reference>0</spring_reference>
          <spring_stiffness>0</spring_stiffness>
        </dynamics>
        <use_parent_model_frame>1</use_parent_model_frame>
      </axis>
    </joint>
    <link name='07DOF_frame6'>
      <pose frame=''>0.520606 -0.000308 -0.115999 -0.785394 -1.57079 -2.35691</pose>
      <inertial>
        <pose frame=''>-0.0061 -0.000751 -0.065828 0 -0 0</pose>
        <mass>0.10793</mass>
        <inertia>
          <ixx>4.42907e-05</ixx>
          <ixy>-4.77866e-08</ixy>
          <ixz>1.52971e-06</ixz>
          <iyy>3.93504e-05</iyy>
          <iyz>1.20425e-07</iyz>
          <izz>4.00861e-05</izz>
        </inertia>
      </inertial>
      <collision name='07DOF_frame6_collision'>
        <pose frame=''>0 0 0 0 -0 0</pose>
        <geometry>
          <mesh>
            <scale>1 1 1</scale>
            <uri>meshes/07DOF_frame6.STL</uri>
          </mesh>
        </geometry>
      </collision>
      <visual name='07DOF_frame6_visual'>
        <pose frame=''>0 0 0 0 -0 0</pose>
        <geometry>
          <mesh>
            <scale>1 1 1</scale>
            <uri>meshes/07DOF_frame6.STL</uri>
          </mesh>
        </geometry>
      </visual>
      <visual name='07DOF_frame6_fixed_joint_lump__camera_visual_1'>
        <pose frame=''>0 0 0 0 -0 1.57</pose>
        <geometry>
          <mesh>
            <scale>1 1 1</scale>
            <uri>meshes/vi_camera.dae</uri>
          </mesh>
        </geometry>
        <material>
          <ambient>1 0 0 1</ambient>
          <diffuse>0.5 0.7 1.0 1.0</diffuse>
          <specular>0.5 0.5 0.5 1</specular>
          <emissive>0 0 0 0</emissive>
        </material>
      </visual>
      <gravity>1</gravity>
      <velocity_decay/>
      <self_collide>0</self_collide>
      <sensor name='camera1' type='camera'>
        <update_rate>60</update_rate>
        <camera name='head'>
          <horizontal_fov>1.39626</horizontal_fov>
          <pose frame=''>0 0 0 3.14 -1.57 -1.57</pose>
          <image>
            <width>640</width>
            <height>480</height>
            <format>R8G8B8</format>
          </image>
          <clip>
            <near>0.02</near>
            <far>300</far>
          </clip>
        </camera>
        <plugin name='camera_controller' filename='libgazebo_ros_camera.so'>
          <alwaysOn>true</alwaysOn>
          <updateRate>0.0</updateRate>
          <cameraName>/camera</cameraName>
          <imageTopicName>image_rect</imageTopicName>
          <cameraInfoTopicName>camera_info</cameraInfoTopicName>
          <frameName>camera</frameName>
          <hackBaseline>0.07</hackBaseline>
          <distortionK1>0.0</distortionK1>
          <distortionK2>0.0</distortionK2>
          <distortionK3>0.0</distortionK3>
          <distortionT1>0.0</distortionT1>
          <distortionT2>0.0</distortionT2>
        </plugin>
        <pose frame=''>0 0 0 0 -0 1.57</pose>
      </sensor>
    </link>
    <joint name='joint6' type='revolute'>
      <child>07DOF_frame6</child>
      <parent>06DOF_frame5</parent>
      <axis>
        <xyz>1 -0.000713 4e-06</xyz>
        <limit>
          <lower>-3.14</lower>
          <upper>3.14</upper>
          <effort>300</effort>
          <velocity>5</velocity>
        </limit>
        <dynamics>
          <damping>0.5</damping>
          <friction>0</friction>
          <spring_reference>0</spring_reference>
          <spring_stiffness>0</spring_stiffness>
        </dynamics>
        <use_parent_model_frame>1</use_parent_model_frame>
      </axis>
    </joint>
    <link name='finger1'>
      <pose frame=''>0.493864 0.011106 -0.115999 7e-06 7e-06 -1.57151</pose>
      <inertial>
        <pose frame=''>0.00951 -0.035505 -0.00612 0 -0 0</pose>
        <mass>0.0102125</mass>
        <inertia>
          <ixx>4.0484e-05</ixx>
          <ixy>5.41208e-07</ixy>
          <ixz>-4.76707e-08</ixz>
          <iyy>3.99381e-05</iyy>
          <iyz>1.53331e-06</iyz>
          <izz>4.5128e-05</izz>
        </inertia>
      </inertial>
      <collision name='finger1_collision'>
        <pose frame=''>0 0 0 0 -0 0</pose>
        <geometry>
          <mesh>
            <scale>1 1 1</scale>
            <uri>meshes/finger1_v2.STL</uri>
          </mesh>
        </geometry>
      </collision>
      <visual name='finger1_visual'>
        <pose frame=''>0 0 0 0 -0 0</pose>
        <geometry>
          <mesh>
            <scale>1 1 1</scale>
            <uri>meshes/finger1_v2.STL</uri>
          </mesh>
        </geometry>
      </visual>
    </link>
    <joint name='joint_finger_1' type='revolute'>
      <child>finger1</child>
      <parent>07DOF_frame6</parent>
      <axis>
        <xyz>-7e-06 -7e-06 1</xyz>
        <limit>
          <lower>-0.3</lower>
          <upper>1.2</upper>
          <effort>300</effort>
          <velocity>5</velocity>
        </limit>
        <dynamics>
          <damping>0.5</damping>
          <friction>0</friction>
          <spring_reference>0</spring_reference>
          <spring_stiffness>0</spring_stiffness>
        </dynamics>
        <use_parent_model_frame>1</use_parent_model_frame>
      </axis>
    </joint>
    <link name='finger2'>
      <pose frame=''>0.493847 -0.012289 -0.115999 -3.14159 7e-06 -1.57151</pose>
      <inertial>
        <pose frame=''>-0.011515 0.035505 0.00612 0 -0 0</pose>
        <mass>0.010212</mass>
        <inertia>
          <ixx>4.0484e-05</ixx>
          <ixy>2.99368e-07</ixy>
          <ixz>4.76707e-08</ixz>
          <iyy>3.99381e-05</iyy>
          <iyz>1.53413e-06</iyz>
          <izz>4.5128e-05</izz>
        </inertia>
      </inertial>
      <collision name='finger2_collision'>
        <pose frame=''>0 0 0 0 -0 0</pose>
        <geometry>
          <mesh>
            <scale>1 1 1</scale>
            <uri>meshes/finger2_v2.STL</uri>
          </mesh>
        </geometry>
      </collision>
      <visual name='finger2_visual'>
        <pose frame=''>0 0 0 0 -0 0</pose>
        <geometry>
          <mesh>
            <scale>1 1 1</scale>
            <uri>meshes/finger2_v2.STL</uri>
          </mesh>
        </geometry>
      </visual>
    </link>
    <joint name='joint_finger_2' type='revolute'>
      <child>finger2</child>
      <parent>07DOF_frame6</parent>
      <axis>
        <xyz>0 7e-06 -1</xyz>
        <limit>
          <lower>-0.3</lower>
          <upper>1.2</upper>
          <effort>300</effort>
          <velocity>5</velocity>
        </limit>
        <dynamics>
          <damping>0.5</damping>
          <friction>0</friction>
          <spring_reference>0</spring_reference>
          <spring_stiffness>0</spring_stiffness>
        </dynamics>
        <use_parent_model_frame>1</use_parent_model_frame>
      </axis>
    </joint>
    <link name='rotor_0'>
      <pose frame=''>0.26701 -0.26701 0.04 0 -0 0</pose>
      <inertial>
        <pose frame=''>0 0 0 0 -0 0</pose>
        <mass>0.009</mass>
        <inertia>
          <ixx>1.755e-06</ixx>
          <ixy>0</ixy>
          <ixz>0</ixz>
          <iyy>0.00120007</iyy>
          <iyz>0</iyz>
          <izz>0.00120169</izz>
        </inertia>
      </inertial>
      <collision name='rotor_0_collision'>
        <pose frame=''>0 0 0 0 -0 0</pose>
        <geometry>
          <cylinder>
            <length>0.005</length>
            <radius>0.2</radius>
          </cylinder>
        </geometry>
        <surface>
          <contact>
            <ode/>
          </contact>
          <friction>
            <ode/>
          </friction>
        </surface>
      </collision>
      <visual name='rotor_0_visual'>
        <pose frame=''>0 0 0 0 -0 0</pose>
        <geometry>
          <mesh>
            <scale>0.2 0.2 0.2</scale>
            <uri>meshes/propeller_ccw.dae</uri>
          </mesh>
        </geometry>
        <material>
          <ambient>1 0 0 1</ambient>
          <diffuse>0.5 0.7 1.0 1.0</diffuse>
          <specular>0.5 0.5 0.5 1</specular>
          <emissive>0 0 0 0</emissive>
        </material>
      </visual>
      <gravity>1</gravity>
      <velocity_decay/>
      <self_collide>0</self_collide>
    </link>
    <joint name='rotor_0_joint' type='revolute'>
      <child>rotor_0</child>
      <parent>base_link</parent>
      <axis>
        <xyz>0 0 1</xyz>
        <limit>
          <lower>-1e+16</lower>
          <upper>1e+16</upper>
        </limit>
        <dynamics>
          <damping>0.5</damping>
          <friction>0</friction>
          <spring_reference>0</spring_reference>
          <spring_stiffness>0</spring_stiffness>
        </dynamics>
        <use_parent_model_frame>1</use_parent_model_frame>
      </axis>
    </joint>
    <link name='rotor_1'>
      <pose frame=''>-0.26701 0.26701 0.04 0 -0 0</pose>
      <inertial>
        <pose frame=''>0 0 0 0 -0 0</pose>
        <mass>0.009</mass>
        <inertia>
          <ixx>1.755e-06</ixx>
          <ixy>0</ixy>
          <ixz>0</ixz>
          <iyy>0.00120007</iyy>
          <iyz>0</iyz>
          <izz>0.00120169</izz>
        </inertia>
      </inertial>
      <collision name='rotor_1_collision'>
        <pose frame=''>0 0 0 0 -0 0</pose>
        <geometry>
          <cylinder>
            <length>0.005</length>
            <radius>0.2</radius>
          </cylinder>
        </geometry>
        <surface>
          <contact>
            <ode/>
          </contact>
          <friction>
            <ode/>
          </friction>
        </surface>
      </collision>
      <visual name='rotor_1_visual'>
        <pose frame=''>0 0 0 0 -0 0</pose>
        <geometry>
          <mesh>
            <scale>0.2 0.2 0.2</scale>
            <uri>meshes/propeller_ccw.dae</uri>
          </mesh>
        </geometry>
        <material>
          <ambient>1 0 0 1</ambient>
          <diffuse>0.5 0.7 1.0 1.0</diffuse>
          <specular>0.5 0.5 0.5 1</specular>
          <emissive>0 0 0 0</emissive>
        </material>
      </visual>
      <gravity>1</gravity>
      <velocity_decay/>
      <self_collide>0</self_collide>
    </link>
    <joint name='rotor_1_joint' type='revolute'>
      <child>rotor_1</child>
      <parent>base_link</parent>
      <axis>
        <xyz>0 0 1</xyz>
        <limit>
          <lower>-1e+16</lower>
          <upper>1e+16</upper>
        </limit>
        <dynamics>
          <damping>0.5</damping>
          <friction>0</friction>
          <spring_reference>0</spring_reference>
          <spring_stiffness>0</spring_stiffness>
        </dynamics>
        <use_parent_model_frame>1</use_parent_model_frame>
      </axis>
    </joint>
    <link name='rotor_2'>
      <pose frame=''>0.26701 0.26701 0.04 0 -0 0</pose>
      <inertial>
        <pose frame=''>0 0 0 0 -0 0</pose>
        <mass>0.009</mass>
        <inertia>
          <ixx>1.755e-06</ixx>
          <ixy>0</ixy>
          <ixz>0</ixz>
          <iyy>0.00120007</iyy>
          <iyz>0</iyz>
          <izz>0.00120169</izz>
        </inertia>
      </inertial>
      <collision name='rotor_2_collision'>
        <pose frame=''>0 0 0 0 -0 0</pose>
        <geometry>
          <cylinder>
            <length>0.005</length>
            <radius>0.2</radius>
          </cylinder>
        </geometry>
        <surface>
          <contact>
            <ode/>
          </contact>
          <friction>
            <ode/>
          </friction>
        </surface>
      </collision>
      <visual name='rotor_2_visual'>
        <pose frame=''>0 0 0 0 -0 0</pose>
        <geometry>
          <mesh>
            <scale>0.2 0.2 0.2</scale>
            <uri>meshes/propeller_cw.dae</uri>
          </mesh>
        </geometry>
        <material>
          <ambient>1 0 0 1</ambient>
          <diffuse>0.5 0.7 1.0 1.0</diffuse>
          <specular>0.5 0.5 0.5 1</specular>
          <emissive>0 0 0 0</emissive>
        </material>
      </visual>
      <gravity>1</gravity>
      <velocity_decay/>
      <self_collide>0</self_collide>
    </link>
    <joint name='rotor_2_joint' type='revolute'>
      <child>rotor_2</child>
      <parent>base_link</parent>
      <axis>
        <xyz>0 0 1</xyz>
        <limit>
          <lower>-1e+16</lower>
          <upper>1e+16</upper>
        </limit>
        <dynamics>
          <damping>0.5</damping>
          <friction>0</friction>
          <spring_reference>0</spring_reference>
          <spring_stiffness>0</spring_stiffness>
        </dynamics>
        <use_parent_model_frame>1</use_parent_model_frame>
      </axis>
    </joint>
    <link name='rotor_3'>
      <pose frame=''>-0.26701 -0.26701 0.04 0 -0 0</pose>
      <inertial>
        <pose frame=''>0 0 0 0 -0 0</pose>
        <mass>0.009</mass>
        <inertia>
          <ixx>1.755e-06</ixx>
          <ixy>0</ixy>
          <ixz>0</ixz>
          <iyy>0.00120007</iyy>
          <iyz>0</iyz>
          <izz>0.00120169</izz>
        </inertia>
      </inertial>
      <collision name='rotor_3_collision'>
        <pose frame=''>0 0 0 0 -0 0</pose>
        <geometry>
          <cylinder>
            <length>0.005</length>
            <radius>0.2</radius>
          </cylinder>
        </geometry>
        <surface>
          <contact>
            <ode/>
          </contact>
          <friction>
            <ode/>
          </friction>
        </surface>
      </collision>
      <visual name='rotor_3_visual'>
        <pose frame=''>0 0 0 0 -0 0</pose>
        <geometry>
          <mesh>
            <scale>0.2 0.2 0.2</scale>
            <uri>meshes/propeller_cw.dae</uri>
          </mesh>
        </geometry>
        <material>
          <ambient>1 0 0 1</ambient>
          <diffuse>0.5 0.7 1.0 1.0</diffuse>
          <specular>0.5 0.5 0.5 1</specular>
          <emissive>0 0 0 0</emissive>
        </material>
      </visual>
      <gravity>1</gravity>
      <velocity_decay/>
      <self_collide>0</self_collide>
    </link>
    <joint name='rotor_3_joint' type='revolute'>
      <child>rotor_3</child>
      <parent>base_link</parent>
      <axis>
        <xyz>0 0 1</xyz>
        <limit>
          <lower>-1e+16</lower>
          <upper>1e+16</upper>
        </limit>
        <dynamics>
          <damping>0.5</damping>
          <friction>0</friction>
          <spring_reference>0</spring_reference>
          <spring_stiffness>0</spring_stiffness>
        </dynamics>
        <use_parent_model_frame>1</use_parent_model_frame>
      </axis>
    </joint>
    <link name='rotor_4'>
      <pose frame=''>0.26701 -0.26701 -0.02 0 -0 0</pose>
      <inertial>
        <pose frame=''>0 0 0 0 -0 0</pose>
        <mass>0.009</mass>
        <inertia>
          <ixx>1.755e-06</ixx>
          <ixy>0</ixy>
          <ixz>0</ixz>
          <iyy>0.00120007</iyy>
          <iyz>0</iyz>
          <izz>0.00120169</izz>
        </inertia>
      </inertial>
      <collision name='rotor_4_collision'>
        <pose frame=''>0 0 0 0 -0 0</pose>
        <geometry>
          <cylinder>
            <length>0.005</length>
            <radius>0.2</radius>
          </cylinder>
        </geometry>
        <surface>
          <contact>
            <ode/>
          </contact>
          <friction>
            <ode/>
          </friction>
        </surface>
      </collision>
      <visual name='rotor_4_visual'>
        <pose frame=''>0 0 0 0 -0 0</pose>
        <geometry>
          <mesh>
            <scale>0.2 0.2 0.2</scale>
            <uri>meshes/propeller_ccw.dae</uri>
          </mesh>
        </geometry>
        <material>
          <ambient>1 0 0 1</ambient>
          <diffuse>0.5 0.7 1.0 1.0</diffuse>
          <specular>0.5 0.5 0.5 1</specular>
          <emissive>0 0 0 0</emissive>
        </material>
      </visual>
      <gravity>1</gravity>
      <velocity_decay/>
      <self_collide>0</self_collide>
    </link>
    <joint name='rotor_4_joint' type='revolute'>
      <child>rotor_4</child>
      <parent>base_link</parent>
      <axis>
        <xyz>0 0 1</xyz>
        <limit>
          <lower>-1e+16</lower>
          <upper>1e+16</upper>
        </limit>
        <dynamics>
          <damping>0.5</damping>
          <friction>0</friction>
          <spring_reference>0</spring_reference>
          <spring_stiffness>0</spring_stiffness>
        </dynamics>
        <use_parent_model_frame>1</use_parent_model_frame>
      </axis>
    </joint>
    <link name='rotor_5'>
      <pose frame=''>-0.26701 0.26701 -0.02 0 -0 0</pose>
      <inertial>
        <pose frame=''>0 0 0 0 -0 0</pose>
        <mass>0.009</mass>
        <inertia>
          <ixx>1.755e-06</ixx>
          <ixy>0</ixy>
          <ixz>0</ixz>
          <iyy>0.00120007</iyy>
          <iyz>0</iyz>
          <izz>0.00120169</izz>
        </inertia>
      </inertial>
      <collision name='rotor_5_collision'>
        <pose frame=''>0 0 0 0 -0 0</pose>
        <geometry>
          <cylinder>
            <length>0.005</length>
            <radius>0.2</radius>
          </cylinder>
        </geometry>
        <surface>
          <contact>
            <ode/>
          </contact>
          <friction>
            <ode/>
          </friction>
        </surface>
      </collision>
      <visual name='rotor_5_visual'>
        <pose frame=''>0 0 0 0 -0 0</pose>
        <geometry>
          <mesh>
            <scale>0.2 0.2 0.2</scale>
            <uri>meshes/propeller_ccw.dae</uri>
          </mesh>
        </geometry>
        <material>
          <ambient>1 0 0 1</ambient>
          <diffuse>0.5 0.7 1.0 1.0</diffuse>
          <specular>0.5 0.5 0.5 1</specular>
          <emissive>0 0 0 0</emissive>
        </material>
      </visual>
      <gravity>1</gravity>
      <velocity_decay/>
      <self_collide>0</self_collide>
    </link>
    <joint name='rotor_5_joint' type='revolute'>
      <child>rotor_5</child>
      <parent>base_link</parent>
      <axis>
        <xyz>0 0 1</xyz>
        <limit>
          <lower>-1e+16</lower>
          <upper>1e+16</upper>
        </limit>
        <dynamics>
          <damping>0.5</damping>
          <friction>0</friction>
          <spring_reference>0</spring_reference>
          <spring_stiffness>0</spring_stiffness>
        </dynamics>
        <use_parent_model_frame>1</use_parent_model_frame>
      </axis>
    </joint>
    <link name='rotor_6'>
      <pose frame=''>0.26701 0.26701 -0.02 0 -0 0</pose>
      <inertial>
        <pose frame=''>0 0 0 0 -0 0</pose>
        <mass>0.009</mass>
        <inertia>
          <ixx>1.755e-06</ixx>
          <ixy>0</ixy>
          <ixz>0</ixz>
          <iyy>0.00120007</iyy>
          <iyz>0</iyz>
          <izz>0.00120169</izz>
        </inertia>
      </inertial>
      <collision name='rotor_6_collision'>
        <pose frame=''>0 0 0 0 -0 0</pose>
        <geometry>
          <cylinder>
            <length>0.005</length>
            <radius>0.2</radius>
          </cylinder>
        </geometry>
        <surface>
          <contact>
            <ode/>
          </contact>
          <friction>
            <ode/>
          </friction>
        </surface>
      </collision>
      <visual name='rotor_6_visual'>
        <pose frame=''>0 0 0 0 -0 0</pose>
        <geometry>
          <mesh>
            <scale>0.2 0.2 0.2</scale>
            <uri>meshes/propeller_cw.dae</uri>
          </mesh>
        </geometry>
        <material>
          <ambient>1 0 0 1</ambient>
          <diffuse>0.5 0.7 1.0 1.0</diffuse>
          <specular>0.5 0.5 0.5 1</specular>
          <emissive>0 0 0 0</emissive>
        </material>
      </visual>
      <gravity>1</gravity>
      <velocity_decay/>
      <self_collide>0</self_collide>
    </link>
    <joint name='rotor_6_joint' type='revolute'>
      <child>rotor_6</child>
      <parent>base_link</parent>
      <axis>
        <xyz>0 0 1</xyz>
        <limit>
          <lower>-1e+16</lower>
          <upper>1e+16</upper>
        </limit>
        <dynamics>
          <damping>0.5</damping>
          <friction>0</friction>
          <spring_reference>0</spring_reference>
          <spring_stiffness>0</spring_stiffness>
        </dynamics>
        <use_parent_model_frame>1</use_parent_model_frame>
      </axis>
    </joint>
    <link name='rotor_7'>
      <pose frame=''>-0.26701 -0.26701 -0.02 0 -0 0</pose>
      <inertial>
        <pose frame=''>0 0 0 0 -0 0</pose>
        <mass>0.009</mass>
        <inertia>
          <ixx>1.755e-06</ixx>
          <ixy>0</ixy>
          <ixz>0</ixz>
          <iyy>0.00120007</iyy>
          <iyz>0</iyz>
          <izz>0.00120169</izz>
        </inertia>
      </inertial>
      <collision name='rotor_7_collision'>
        <pose frame=''>0 0 0 0 -0 0</pose>
        <geometry>
          <cylinder>
            <length>0.005</length>
            <radius>0.2</radius>
          </cylinder>
        </geometry>
        <surface>
          <contact>
            <ode/>
          </contact>
          <friction>
            <ode/>
          </friction>
        </surface>
      </collision>
      <visual name='rotor_7_visual'>
        <pose frame=''>0 0 0 0 -0 0</pose>
        <geometry>
          <mesh>
            <scale>0.2 0.2 0.2</scale>
            <uri>meshes/propeller_cw.dae</uri>
          </mesh>
        </geometry>
        <material>
          <ambient>1 0 0 1</ambient>
          <diffuse>0.5 0.7 1.0 1.0</diffuse>
          <specular>0.5 0.5 0.5 1</specular>
          <emissive>0 0 0 0</emissive>
        </material>
      </visual>
      <gravity>1</gravity>
      <velocity_decay/>
      <self_collide>0</self_collide>
    </link>
    <joint name='rotor_7_joint' type='revolute'>
      <child>rotor_7</child>
      <parent>base_link</parent>
      <axis>
        <xyz>0 0 1</xyz>
        <limit>
          <lower>-1e+16</lower>
          <upper>1e+16</upper>
        </limit>
        <dynamics>
          <damping>0.5</damping>
          <friction>0</friction>
          <spring_reference>0</spring_reference>
          <spring_stiffness>0</spring_stiffness>
        </dynamics>
        <use_parent_model_frame>1</use_parent_model_frame>
      </axis>
    </joint>
    <plugin name='realsense' filename='librealsense_gazebo_plugin.so'>
      <prefix>realsense</prefix>
      <depthUpdateRate>60.0</depthUpdateRate>
      <colorUpdateRate>60.0</colorUpdateRate>
      <infraredUpdateRate>60.0</infraredUpdateRate>
      <depthTopicName>depth/image_raw</depthTopicName>
      <depthCameraInfoTopicName>depth/camera_info</depthCameraInfoTopicName>
      <colorTopicName>color/image_raw</colorTopicName>
      <colorCameraInfoTopicName>color/camera_info</colorCameraInfoTopicName>
      <infrared1TopicName>infra1/image_raw</infrared1TopicName>
      <infrared1CameraInfoTopicName>infra1/camera_info</infrared1CameraInfoTopicName>
      <infrared2TopicName>infra2/image_raw</infrared2TopicName>
      <infrared2CameraInfoTopicName>infra2/camera_info</infrared2CameraInfoTopicName>
      <colorOpticalframeName>camera_color_optical_frame</colorOpticalframeName>
      <depthOpticalframeName>camera_depth_optical_frame</depthOpticalframeName>
      <infrared1OpticalframeName>camera_left_ir_optical_frame</infrared1OpticalframeName>
      <infrared2OpticalframeName>camera_right_ir_optical_frame</infrared2OpticalframeName>
      <rangeMinDepth>0.2</rangeMinDepth>
      <rangeMaxDepth>10.0</rangeMaxDepth>
      <pointCloud>true</pointCloud>
      <pointCloudTopicName>depth/points</pointCloudTopicName>
      <pointCloudCutoff>0.5</pointCloudCutoff>
      <pointCloudCutoffMax>9.0</pointCloudCutoffMax>
    </plugin>
  </model>
</sdf>
