<?xml version="1.0" ?>
<robot name="robot_arm">
  <joint name="joint1" type="revolute">
    <parent link="robot_arm__base"/>
    <child link="robot_arm__arm"/>
    <origin rpy="0 0 0" xyz="0.007   0.0001 -0.0211"/>
    <axis xyz="0 1 0"/>
    <dynamics damping="0.01" friction="0.0" />
    <limit effort="300.0" lower="0.4" upper="2.9" velocity="50.0"/>
    <physics>
      <ode>
        <limit>
          <cfm>0</cfm>
          <erp>0.2</erp>
        </limit>
        <suspension>
          <cfm>0</cfm>
          <erp>0.2</erp>
        </suspension>
      </ode>
    </physics>
  </joint>
  <link name="robot_arm__base">
    <inertial>
      <mass value="0.142"/>
      <origin rpy="0 0 0" xyz="-1.020e-03 -4.000e-05 -1.439e-02"/>
      <inertia ixx="0.000065677" ixy="-0.000000330" ixz="-0.000005073" iyy="0.000156934" iyz="0.000000112" izz="0.000179185"/>
    </inertial>
    <collision name="robot_arm__base_collision">
      <origin rpy="0 0 0" xyz="0    0   -0.02"/>
      <geometry>
        <box size="0.15 0.1 0.05"/>
      </geometry>
    </collision>
    <visual name="robot_arm__base_visual">
      <origin rpy="0 0 0" xyz="0 0 0"/>
      <geometry>
        <mesh filename="package://aerial_catcher/description/meshes/Arm1113_1.STL" scale="1 1 1"/>
      </geometry>
    </visual>
  </link>
  <link name="robot_arm__arm">
    <inertial>
      <mass value="0.069"/>
      <origin rpy="0 0 0" xyz="0.17389  0.00165 -0.00152"/>
      <inertia ixx="79.613e-06" ixy="0.00000000000" ixz="-0.000017458" iyy="0.000768697" iyz="0.00000000000" izz="0.000840273"/>
    </inertial>
    <collision name="robot_arm__arm_collision">
      <origin rpy="0 0 0" xyz="0.2 0  0"/>
      <geometry>
        <box size="0.4 0.1 0.03"/>
      </geometry>
    </collision>
    <visual name="robot_arm__arm_visual">
      <origin rpy="0 0 0" xyz="0 0 0"/>
      <geometry>
        <mesh filename="package://aerial_catcher/description/meshes/Arm1113_2.STL" scale="1 1 1"/>
      </geometry>
    </visual>
  </link>

  <link name="world"/>
  <joint name="toworld" type="fixed">
    <parent link="world"/>
    <child link="robot_arm__base"/>
    <origin rpy="0 0 0" xyz="0.007   0.0001 1.0"/>
  </joint>
  <!-- <transmission name="tran2">
        <type>transmission_interface/SimpleTransmission</type>
        <joint name="joint1">
            <hardwareInterface>hardware_interface/VelocityJointInterface</hardwareInterface>
        </joint>
        <actuator name="motor1">
            <hardwareInterface>hardware_interface/VelocityJointInterface</hardwareInterface>
            <mechanicalReduction>1</mechanicalReduction>
        </actuator>
    </transmission> -->
  <transmission name="tran2">
    <type>transmission_interface/SimpleTransmission</type>
    <joint name="joint1">
      <hardwareInterface>hardware_interface/EffortJointInterface</hardwareInterface>
    </joint>
    <actuator name="motor1">
      <hardwareInterface>hardware_interface/PositionJointInterface</hardwareInterface>
      <mechanicalReduction>1</mechanicalReduction>
    </actuator>
  </transmission>
  <!-- <transmission name="tran2">
        <type>transmission_interface/SimpleTransmission</type>
        <joint name="joint1">
            <hardwareInterface>hardware_interface/PositionJointInterface</hardwareInterface>
        </joint>
        <actuator name="motor1">
            <hardwareInterface>hardware_interface/PositionJointInterface</hardwareInterface>
            <mechanicalReduction>1</mechanicalReduction>
        </actuator>
    </transmission> -->

  <gazebo reference="robot_arm__arm">
    <sensor type="contact" name="my_contact">
      <update_rate>5</update_rate>
      <always_on>1</always_on>
      <contact>
        <collision>robot_arm__arm_collision</collision>
      </contact>
      <plugin name="my_plugin" filename="libcontact.so"/>
    </sensor>
  </gazebo>
  <gazebo reference="joint1">
    <provideFeedback>true</provideFeedback>
  </gazebo>
  <gazebo>
    <plugin name="gazebo_ros_control" filename="libgazebo_ros_control.so">
      <robotNamespace>/</robotNamespace>
      <robotSimType>gazebo_ros_control/DefaultRobotHWSim</robotSimType>
      <legacyModeNS>true</legacyModeNS>
    </plugin>
    <plugin name="ft_sensor" filename="libgazebo_ros_ft_sensor.so">
      <updateRate>50.0</updateRate>
      <topicName>/joint1/ft</topicName>
      <jointName>joint1</jointName>
    </plugin>
  </gazebo>
</robot>